Workbook

Sheet groupe
A1: ETU003240 | B1: A

Sheet liste des taches
A1: Ligne | B1: Catégorie | C1: Module | D1: Page | E1: Description tâche | F1: Type | G1: Qui | H1: Estimation | I1: Temps passé | J1: Reste à faire | K1: Avancement
A2: 1 | B2: Backoffice | C2: Gestion Login | D2: Login | E2: Formulaire login avec login/mdp par defaut | F2: Affichage | G2: ETU003240 | H2: 30 | I2: =detail_avancement!B8 -> 45 | J2: 0 | K2: =(I2/(I2+J2)) -> 1
A3: 2 | B3: Backoffice | C3: Gestion Login | D3: Login | E3: Protection des pages backoffice (auth guard) | F3: Metier | G3: ETU003240 | H3: 45 | I3: =detail_avancement!B9 -> 25 | J3: 0 | K3: =(I3/(I3+J3)) -> 1
A4: 3 | B4: Backoffice | C4: Gestion Login | D4: Login | E4: Verification credentials et session | F4: Integration | G4: ETU003240 | H4: 30 | I4: =detail_avancement!B10 -> 30 | J4: 0 | K4: =(I4/(I4+J4)) -> 1
A5: 4 | B5: Backoffice | C5: Import Données | D5: Import | E5: Page import avec bouton reset donnees | F5: Affichage | G5: ETU003240 | H5: 20 | I5: =detail_avancement!B11 -> 20 | J5: 0 | K5: =(I5/(I5+J5)) -> 1
A6: 5 | B6: Backoffice | C6: Import Données | D6: Import | E6: Import 3 fichiers CSV (produits/categories/commandes) | F6: Metier | G6: ETU003240 | H6: 60 | I6: =detail_avancement!B12 -> 30 | J6: 0 | K6: =(I6/(I6+J6)) -> 1
A7: 6 | B7: Backoffice | C7: Import Données | D7: Import | E7: Import fichier ZIP images | F7: Metier | G7: ETU003240 | H7: 30 | I7: =detail_avancement!B13 -> 25 | J7: 0 | K7: =(I7/(I7+J7)) -> 1
A8: 7 | B8: Backoffice | C8: Import Données | D8: Import | E8: Traitement et sauvegarde donnees importees | F8: Integration | G8: ETU003240 | H8: 45 | I8: =detail_avancement!B14 -> 30 | J8: 0 | K8: =(I8/(I8+J8)) -> 1
A9: 8 | B9: Backoffice | C9: Gestion Commandes | D9: Commandes | E9: Page liste des commandes | F9: Affichage | G9: ETU003240 | H9: 25 | I9: =detail_avancement!B15 -> 35 | J9: 0 | K9: =(I9/(I9+J9)) -> 1
A10: 9 | B10: Backoffice | C10: Gestion Commandes | D10: Commandes | E10: Modification etat commande (payement effectue/annule) | F10: Metier | G10: ETU003240 | H10: 30 | I10: =detail_avancement!B16 -> 25 | J10: 0 | K10: =(I10/(I10+J10)) -> 1
A11: 10 | B11: Backoffice | C11: Gestion Commandes | D11: Commandes | E11: Persistance etat commande en base | F11: Integration | G11: ETU003240 | H11: 20 | I11: =detail_avancement!B17 -> 25 | J11: 0 | K11: =(I11/(I11+J11)) -> 1
A12: 11 | B12: Frontoffice | C12: Catalogue Produits | D12: Accueil | E12: Page d'accueil liste des produits | F12: Affichage | G12: ETU003240 | H12: 30 | I12: =detail_avancement!B18 -> 15 | J12: 0 | K12: =(I12/(I12+J12)) -> 1
A13: 12 | B13: Frontoffice | C13: Catalogue Produits | D13: Fiche Produit | E13: Fiche produit detaillee | F13: Affichage | G13: ETU003240 | H13: 25 | I13: =detail_avancement!B19 -> 30 | J13: 0 | K13: =(I13/(I13+J13)) -> 1
... A52: 51 | B52: Frontoffice | C52: Catalogue Produits | D52: Fiche Produit | E52: Recuperation stock en temps reel depuis Prestashop | F52: Integration | G52: ETU003240 | H52: 15 | I52: =detail_avancement!B58 -> 0 | J52: 0 | K52: =(I52/(I52+J52)) -> #DIV/0!

Sheet Recap
B1: Data
A2: Qui | B2: SUM of Estimation | C2: SUM of Temps passé | D2: SUM of Reste à faire
A3: (empty)
A4: ETU003240 | B4: 1260 | C4: 1045 | D4: 0
A5: Total Result | B5: 1260 | C5: 1045 | D5: 0
A12: Avancement | B12: =avancement!D2 -> 1

Sheet avancement
A1: estimation total | B1: temps passé total | C1: reste à faire total | D1: avancement | E1: dépassement
A2: =SUM('liste des taches'!H2:H45) -> 1110 | B2: =SUM('liste des taches'!I2:I45) -> 1030 | C2: =SUM('liste des taches'!J2:J45) -> 0 | D2: =IF((B2+C2)=0,0,B2/(B2+C2)) -> 1 | E2: =IF(B2=0,0,B2/A2) -> 0.92792793
C3: =C2/60 -> 0 | D3: heure

Sheet detail_avancement
A1: Ligne | B1: Total | C1: 46153 | D1: 46154 | E1: 46155 | F1: 46156 | G1: 46157 | H1: 46158 | I1: 46159
A2: 1 | B2: =SUM(C2:I2) -> 30 | C2: 30
A3: 2 | B3: =SUM(C3:I3) -> 45 | C3: 45
A4: 3 | B4: =SUM(C4:I4) -> 30 | C4: 30
A5: 4 | B5: =SUM(C5:I5) -> 20 | C5: 20
A6: 5 | B6: =SUM(C6:I6) -> 60 | C6: 60
A7: 6 | B7: =SUM(C7:I7) -> 30 | C7: 30
A8: 7 | B8: =SUM(C8:I8) -> 45 | C8: 45
A9: 8 | B9: =SUM(C9:I9) -> 25 | C9: 25
A10: 9 | B10: =SUM(C10:I10) -> 30 | C10: 30
A11: 10 | B11: =SUM(C11:I11) -> 20 | C11: 20
A12: 11 | B12: =SUM(C12:I12) -> 30 | D12: 30
A13: 12 | B13: =SUM(C13:I13) -> 25 | D13: 25
A14: 13 | B14: =SUM(C14:I14) -> 30 | D14: 30
A15: 14 | B15: =SUM(C15:I15) -> 35 | D15: 35
A16: 15 | B16: =SUM(C16:I16) -> 25 | D16: 25
A17: 16 | B17: =SUM(C17:I17) -> 25 | D17: 25
A18: 17 | B18: =SUM(C18:I18) -> 15 | D18: 15
A19: 18 | B19: =SUM(C19:I19) -> 30 | D19: 30
A20: 19 | B20: =SUM(C20:I20) -> 20 | D20: 20
A21: 20 | B21: =SUM(C21:I21) -> 20 | D21: 20
A22: 21 | B22: =SUM(C22:I22) -> 30 | D22: 30
A23: 22 | B23: =SUM(C23:I23) -> 25 | D23: 25
A24: 23 | B24: =SUM(C24:I24) -> 20 | E24: 20
A25: 24 | B25: =SUM(C25:I25) -> 25 | E25: 25
A26: 25 | B26: =SUM(C26:I26) -> 30 | E26: 30
A27: 26 | B27: =SUM(C27:I27) -> 20 | E27: 20
A28: 27 | B28: =SUM(C28:I28) -> 20 | E28: 20
A29: 28 | B29: =SUM(C29:I29) -> 35 | E29: 35
A30: 29 | B30: =SUM(C30:I30) -> 30 | E30: 30
A31: 30 | B31: =SUM(C31:I31) -> 30 | F31: 30
A32: 31 | B32: =SUM(C32:I32) -> 15 | F32: 15
A33: 32 | B33: =SUM(C33:I33) -> 20 | F33: 20
A34: 33 | B34: =SUM(C34:I34) -> 20 | F34: 20
A35: 34 | B35: =SUM(C35:I35) -> 15 | F35: 15
A36: 35 | B36: =SUM(C36:I36) -> 15 | F36: 15
A37: 36 | B37: =SUM(C37:I37) -> 25 | F37: 25
A38: 37 | B38: =SUM(C38:I38) -> 20 | F38: 20
A39: 38 | B39: =SUM(C39:I39) -> 15 | F39: 15
A40: 39 | B40: =SUM(C40:I40) -> 15 | F40: 15
...
